Workbook

Sheet products
A1: Product ID | B1: Product Name | C1: Category | D1: Brand | E1: Price | F1: Stock
A2: P1001 | B2: Laptop | C2: Electronics | D2: Dell | E2: 55000 | F2: 25
A3: P1002 | B3: Smartphone | C3: Electronics | D3: Samsung | E3: 32000 | F3: 40
A4: P1003 | B4: Headphones | C4: Electronics | D4: Sony | E4: 4500 | F4: 80
A5: P1004 | B5: Keyboard | C5: Accessories | D5: Logitech | E5: 1800 | F5: 65
A6: P1005 | B6: Mouse | C6: Accessories | D6: HP | E6: 900 | F6: 120
A7: P1006 | B7: Printer | C7: Electronics | D7: Canon | E7: 12500 | F7: 18
A8: P1007 | B8: Office Chair | C8: Furniture | D8: Green Soul | E8: 8500 | F8: 20
A9: P1008 | B9: Office Desk | C9: Furniture | D9: IKEA | E9: 12000 | F9: 15
A10: P1009 | B10: Monitor | C10: Electronics | D10: LG | E10: 16000 | F10: 30
A11: P1010 | B11: Webcam | C11: Accessories | D11: Logitech | E11: 3500 | F11: 50

Sheet answer
A1: 1
B3: Product ID | C3: Product Name
B4: P1006 | C4: =INDEX(products!B:B, MATCH(B4, products!A:A, 0)) -> Printer
A7: 2 | B7: Product ID | C7: Price
B8: P1008 | C8: =INDEX(products!A1:F11,MATCH(B8,products!A:A,0),5) -> 12000
A10: 3 | B10: Product ID | C10: brand
B11: P1003 | C11: =INDEX(products!$A$1:$F$11,MATCH(answer!B11,products!A:A,0),4) -> Sony
A13: 4 | B13: Product ID | C13: stock
B14: P1005 | C14: =INDEX(products!$A$1:$F$11,MATCH(answer!B14,products!A:A,0),6) -> 120
A16: 5 | B16: Product ID | C16: category
B17: P1004 | C17: =INDEX(products!$A$1:$F$11,MATCH(answer!B17,products!A:A,0),4) -> Logitech
A19: 6 | B19: cus ID | C19: cust name
B20: C007 | C20: =INDEX(customers!$A$1:$E$11,MATCH(answer!B20,customers!A:A,0),2) -> Rohan Gupta
A22: 7 | B22: cus ID | C22: city
B23: C010 | C23: =INDEX(customers!$A$1:$E$11,MATCH(answer!B23,customers!A:A,0),3) -> Kochi
A25: 8 | B25: cus ID | C25: state
B26: C003 | C26: =INDEX(customers!$A$1:$E$11,MATCH(answer!B26,customers!A:A,0),4) -> Maharashtra
A28: 9 | B28: cus ID | C28: gender
B29: C006 | C29: =INDEX(customers!$A$1:$E$11,MATCH(answer!B29,customers!A:A,0),5) -> Female
A31: 10 | B31: store id | C31: name
B32: S003 | C32: =INDEX(stores!$A$1:$D$6,MATCH(answer!B32,stores!A:A,0),2) -> Central Store
A34: 11 | B34: store id | C34: city
B35: S005 | C35: =INDEX(stores!$A$1:$D$6,MATCH(answer!B35,stores!A:A,0),3) -> Jaipur
A37: 12 | B37: store id | C37: state
B38: S002 | C38: =INDEX(stores!$A$1:$D$6,MATCH(answer!B38,stores!A:A,0),4) -> Gujarat
A40: 13 | B40: Product ID | C40: Product Name
B41: P1001 | C41: =INDEX(products!$A$1:$F$11,MATCH(answer!B41,answer!$B$40:$B$50,0),2) -> Laptop
B42: P1002 | C42: =INDEX(products!$A$1:$F$11,MATCH(answer!B42,answer!$B$40:$B$50,0),2) -> Smartphone
B43: P1003 | C43: =INDEX(products!$A$1:$F$11,MATCH(answer!B43,answer!$B$40:$B$50,0),2) -> Headphones
B44: P1004 | C44: =INDEX(products!$A$1:$F$11,MATCH(answer!B44,answer!$B$40:$B$50,0),2) -> Keyboard
B45: P1005 | C45: =INDEX(products!$A$1:$F$11,MATCH(answer!B45,answer!$B$40:$B$50,0),2) -> Mouse
B46: P1006 | C46: =INDEX(products!$A$1:$F$11,MATCH(answer!B46,answer!$B$40:$B$50,0),2) -> Printer
B47: P1007 | C47: =INDEX(products!$A$1:$F$11,MATCH(answer!B47,answer!$B$40:$B$50,0),2) -> Office Chair
B48: P1008 | C48: =INDEX(products!$A$1:$F$11,MATCH(answer!B48,answer!$B$40:$B$50,0),2) -> Office Desk
B49: P1009 | C49: =INDEX(products!$A$1:$F$11,MATCH(answer!B49,answer!$B$40:$B$50,0),2) -> Monitor
B50: P1010 | C50: =INDEX(products!$A$1:$F$11,MATCH(answer!B50,answer!$B$40:$B$50,0),2) -> Webcam
A53: 14 | B53: Customer ID | C53: Customer Name
B54: C001 | C54: =INDEX(customers!$A$1:$E$11,MATCH(answer!B54,answer!$B$53:$B$63,0),2) -> Amit Patel
B55: C002 | C55: =INDEX(customers!$A$1:$E$11,MATCH(answer!B55,answer!$B$53:$B$63,0),2) -> Priya Shah
B56: C003 | C56: =INDEX(customers!$A$1:$E$11,MATCH(answer!B56,answer!$B$53:$B$63,0),2) -> Rahul Mehta
...

Sheet task
A1: # Practice Tasks
A3: ## Beginner
A5: ### Task 1
A7: Find the **Product Name** for Product ID **P1006**.
A9: ### Task 2
A11: Find the **Price** for Product ID **P1008**.
A13: ### Task 3
A15: Find the **Brand** for Product ID **P1003**.
A17: ### Task 4
A19: Find the **Stock** for Product ID **P1005**.
A21: ### Task 5
A23: Find the **Category** for Product ID **P1004**.
... A120: > Use **INDEX + MATCH** for every lookup field.

Sheet sales
A1: Sale ID | B1: Product ID | C1: Customer ID | D1: Quantity | E1: Date | F1: Store ID
A2: SA001 | B2: P1001 | C2: C001 | D2: 1 | E2: 46023 | F2: S001
A3: SA002 | B3: P1005 | C3: C002 | D3: 3 | E3: 46024 | F3: S002
A4: SA003 | B4: P1003 | C4: C003 | D4: 2 | E4: 46025 | F4: S003
A5: SA004 | B5: P1009 | C5: C004 | D5: 1 | E5: 46026 | F5: S004
A6: SA005 | B6: P1002 | C6: C005 | D6: 2 | E6: 46027 | F6: S005
A7: SA006 | B7: P1007 | C7: C006 | D7: 1 | E7: 46028 | F7: S001
A8: SA007 | B8: P1006 | C8: C007 | D8: 1 | E8: 46029 | F8: S002
A9: SA008 | B9: P1010 | C9: C008 | D9: 2 | E9: 46030 | F9: S003
A10: SA009 | B10: P1004 | C10: C009 | D10: 4 | E10: 46031 | F10: S004
A11: SA010 | B11: P1008 | C11: C010 | D11: 1 | E11: 46032 | F11: S005
A12: SA011 | B12: P1005 | C12: C001 | D12: 5 | E12: 46033 | F12: S001
A13: SA012 | B13: P1003 | C13: C002 | D13: 3 | E13: 46034 | F13: S002
... A16: SA015 | B16: P1002 | C16: C005 | D16: 1 | E16: 46037 | F16: S005

Sheet customers
A1: Customer ID | B1: Customer Name | C1: City | D1: State | E1: Gender
A2: C001 | B2: Amit Patel | C2: Ahmedabad | D2: Gujarat | E2: Male
A3: C002 | B3: Priya Shah | C3: Surat | D3: Gujarat | E3: Female
A4: C003 | B4: Rahul Mehta | C4: Mumbai | D4: Maharashtra | E4: Male
A5: C004 | B5: Sneha Joshi | C5: Pune | D5: Maharashtra | E5: Female
A6: C005 | B6: Arjun Singh | C6: Jaipur | D6: Rajasthan | E6: Male
A7: C006 | B7: Neha Verma | C7: Delhi | D7: Delhi | E7: Female
A8: C007 | B8: Rohan Gupta | C8: Indore | D8: Madhya Pradesh | E8: Male
A9: C008 | B9: Pooja Sharma | C9: Lucknow | D9: Uttar Pradesh | E9: Female
A10: C009 | B10: Karan Desai | C10: Vadodara | D10: Gujarat | E10: Male
A11: C010 | B11: Anjali Nair | C11: Kochi | D11: Kerala | E11: Female

Sheet stores
A1: Store ID | B1: Store Name | C1: City | D1: State
A2: S001 | B2: Alpha Store | C2: Ahmedabad | D2: Gujarat
A3: S002 | B3: Beta Store | C3: Surat | D3: Gujarat
A4: S003 | B4: Central Store | C4: Mumbai | D4: Maharashtra
A5: S004 | B5: Digital Hub | C5: Pune | D5: Maharashtra
A6: S005 | B6: Smart World | C6: Jaipur | D6: Rajasthan
