Workbook

Sheet product
A1: Product ID | B1: Product Name | C1: Category | D1: Brand | E1: Price | F1: Stock
A2: P1001 | B2: Laptop | C2: Electronics | D2: Dell | E2: 55000 | F2: 25
A3: P1002 | B3: Smartphone | C3: Electronics | D3: Samsung | E3: 32000 | F3: 40
A4: P1003 | B4: Headphones | C4: Electronics | D4: Sony | E4: 4500 | F4: 80
A5: P1004 | B5: Keyboard | C5: Accessories | D5: Logitech | E5: 1800 | F5: 65
A6: P1005 | B6: Mouse | C6: Accessories | D6: HP | E6: 900 | F6: 120
A7: P1006 | B7: Printer | C7: Electronics | D7: Canon | E7: 12500 | F7: 18
A8: P1007 | B8: Office Chair | C8: Furniture | D8: Green Soul | E8: 8500 | F8: 20
A9: P1008 | B9: Office Desk | C9: Furniture | D9: IKEA | E9: 12000 | F9: 15
A10: P1009 | B10: Monitor | C10: Electronics | D10: LG | E10: 16000 | F10: 30
A11: P1010 | B11: Webcam | C11: Accessories | D11: Logitech | E11: 3500 | F11: 50
G16: Task 1 | H16: P1006 | I16: =INDEX(Table2[#All],MATCH(H16,Table2[[#All],[Product ID]]),2) -> Printer
G17: Task 2 | H17: P1008 | I17: =INDEX(Table2[#All],MATCH(H17,Table2[[#All],[Product ID]]),5) -> 12000
G18: Task 3 | H18: P1003 | I18: =INDEX(Table2[#All],MATCH(H18,Table2[[#All],[Product ID]]),4) -> Sony
G19: Task 4 | H19: P1005 | I19: =INDEX(Table2[#All],MATCH(H19,Table2[[#All],[Product ID]]),6) -> 120
G20: Task 5 | H20: P1004 | I20: =INDEX(Table2[#All],MATCH(H20,Table2[[#All],[Product ID]]),3) -> Accessories

Sheet customer
A1: Customer ID | B1: Customer Name | C1: City | D1: State | E1: Gender
A2: C001 | B2: Amit Patel | C2: Ahmedabad | D2: Gujarat | E2: Male
A3: C002 | B3: Priya Shah | C3: Surat | D3: Gujarat | E3: Female
A4: C003 | B4: Rahul Mehta | C4: Mumbai | D4: Maharashtra | E4: Male | G4: Task 6
A5: C004 | B5: Sneha Joshi | C5: Pune | D5: Maharashtra | E5: Female | G5: Find the Customer Name for C007. | H5: C007 | I5: =INDEX(Table4[#All],MATCH(H5,Table4[[#All],[Customer ID]]),2) -> Rohan Gupta
A6: C005 | B6: Arjun Singh | C6: Jaipur | D6: Rajasthan | E6: Male | G6: Task 7
A7: C006 | B7: Neha Verma | C7: Delhi | D7: Delhi | E7: Female | G7: Find the City for C010. | H7: C010 | I7: =INDEX(Table4[#All],MATCH(H7,Table4[[#All],[Customer ID]]),3) -> Kochi
A8: C007 | B8: Rohan Gupta | C8: Indore | D8: Madhya Pradesh | E8: Male | G8: Task 8
A9: C008 | B9: Pooja Sharma | C9: Lucknow | D9: Uttar Pradesh | E9: Female | G9: Find the State for C003. | H9: C003 | I9: =INDEX(Table4[#All],MATCH(H9,Table4[[#All],[Customer ID]]),4) -> Maharashtra
A10: C009 | B10: Karan Desai | C10: Vadodara | D10: Gujarat | E10: Male | G10: Task 9
A11: C010 | B11: Anjali Nair | C11: Kochi | D11: Kerala | E11: Female | G11: Find the Gender for C006. | H11: C006 | I11: =INDEX(Table4[#All],MATCH(H11,Table4[[#All],[Customer ID]]),5) -> Female

Sheet store
A1: Store ID | B1: Store Name | C1: City | D1: State
A2: S001 | B2: Alpha Store | C2: Ahmedabad | D2: Gujarat
A3: S002 | B3: Beta Store | C3: Surat | D3: Gujarat | F3: Task 10
A4: S003 | B4: Central Store | C4: Mumbai | D4: Maharashtra | F4: Find the Store Name for S003. | G4: S003 | H4: =INDEX(Table5[#All],MATCH(G4,Table5[[#All],[Store ID]]),2) -> Central Store
A5: S004 | B5: Digital Hub | C5: Pune | D5: Maharashtra | F5: Task 11
A6: S005 | B6: Smart World | C6: Jaipur | D6: Rajasthan | F6: Find the Store City for S005. | G6: S005 | H6: =INDEX(Table5[#All],MATCH(G6,Table5[[#All],[Store ID]]),3) -> Jaipur
F7: Task 12
F8: Find the Store State for S002 | G8: S002 | H8: =INDEX(Table5[#All],MATCH(G8,Table5[[#All],[Store ID]]),4) -> Gujarat

Sheet sales
A1: Sale ID | B1: Product ID | C1: Customer ID | D1: Quantity | E1: Date | F1: Store ID
A2: SA001 | B2: P1001 | C2: C001 | D2: 1 | E2: 46023 | F2: S001
A3: SA002 | B3: P1005 | C3: C002 | D3: 3 | E3: 46024 | F3: S002
A4: SA003 | B4: P1003 | C4: C003 | D4: 2 | E4: 46025 | F4: S003 | H4: Task 13 | I4: SA001 | J4: P1001 | K4: =INDEX(Table2[],MATCH(J4,product!$A$2:$A$11),2) -> Laptop
A5: SA004 | B5: P1009 | C5: C004 | D5: 1 | E5: 46026 | F5: S004 | H5: Retrieve the Product Name for every Product ID in the Sales sheet. | I5: SA002 | J5: P1005 | K5: =INDEX(Table2[],MATCH(J5,product!$A$2:$A$11),2) -> Mouse
A6: SA005 | B6: P1002 | C6: C005 | D6: 2 | E6: 46027 | F6: S005 | I6: SA003 | J6: P1003 | K6: =INDEX(Table2[],MATCH(J6,product!$A$2:$A$11),2) -> Headphones
A7: SA006 | B7: P1007 | C7: C006 | D7: 1 | E7: 46028 | F7: S001 | I7: SA004 | J7: P1009 | K7: =INDEX(Table2[],MATCH(J7,product!$A$2:$A$11),2) -> Monitor
A8: SA007 | B8: P1006 | C8: C007 | D8: 1 | E8: 46029 | F8: S002 | I8: SA005 | J8: P1002 | K8: =INDEX(Table2[],MATCH(J8,product!$A$2:$A$11),2) -> Smartphone
A9: SA008 | B9: P1010 | C9: C008 | D9: 2 | E9: 46030 | F9: S003 | I9: SA006 | J9: P1007 | K9: =INDEX(Table2[],MATCH(J9,product!$A$2:$A$11),2) -> Office Chair
A10: SA009 | B10: P1004 | C10: C009 | D10: 4 | E10: 46031 | F10: S004 | I10: SA007 | J10: P1006 | K10: =INDEX(Table2[],MATCH(J10,product!$A$2:$A$11),2) -> Printer
A11: SA010 | B11: P1008 | C11: C010 | D11: 1 | E11: 46032 | F11: S005 | I11: SA008 | J11: P1010 | K11: =INDEX(Table2[],MATCH(J11,product!$A$2:$A$11),2) -> Webcam
A12: SA011 | B12: P1005 | C12: C001 | D12: 5 | E12: 46033 | F12: S001 | I12: SA009 | J12: P1004 | K12: =INDEX(Table2[],MATCH(J12,product!$A$2:$A$11),2) -> Keyboard
A13: SA012 | B13: P1003 | C13: C002 | D13: 3 | E13: 46034 | F13: S002 | I13: SA010 | J13: P1008 | K13: =INDEX(Table2[],MATCH(J13,product!$A$2:$A$11),2) -> Office Desk
A14: SA013 | B14: P1001 | C14: C003 | D14: 1 | E14: 46035 | F14: S003 | I14: SA011 | J14: P1005 | K14: =INDEX(Table2[],MATCH(J14,product!$A$2:$A$11),2) -> Mouse
A15: SA014 | B15: P1009 | C15: C004 | D15: 2 | E15: 46036 | F15: S004 | I15: SA012 | J15: P1003 | K15: =INDEX(Table2[],MATCH(J15,product!$A$2:$A$11),2) -> Headphones
A16: SA015 | B16: P1002 | C16: C005 | D16: 1 | E16: 46037 | F16: S005 | I16: SA013 | J16: P1001 | K16: =INDEX(Table2[],MATCH(J16,product!$A$2:$A$11),2) -> Laptop
I17: SA014 | J17: P1009 | K17: =INDEX(Table2[],MATCH(J17,product!$A$2:$A$11),2) -> Monitor
I18: SA015 | J18: P1002 | K18: =INDEX(Table2[],MATCH(J18,product!$A$2:$A$11),2) -> Smartphone
H21: Task 14
H22: Retrieve the Customer Name for every Customer ID in the Sales sheet. | I22: C001 | J22: =INDEX(Table4[],MATCH(I22,Table4[Customer ID]),2) -> Amit Patel
I23: C002 | J23: =INDEX(Table4[],MATCH(I23,Table4[Customer ID]),2) -> Priya Shah
I24: C003 | J24: =INDEX(Table4[],MATCH(I24,Table4[Customer ID]),2) -> Rahul Mehta
I25: C004 | J25: =INDEX(Table4[],MATCH(I25,Table4[Customer ID]),2) -> Sneha Joshi
I26: C005 | J26: =INDEX(Table4[],MATCH(I26,Table4[Customer ID]),2) -> Arjun Singh
I27: C006 | J27: =INDEX(Table4[],MATCH(I27,Table4[Customer ID]),2) -> Neha Verma
I28: C007 | J28: =INDEX(Table4[],MATCH(I28,Table4[Customer ID]),2) -> Rohan Gupta
I29: C008 | J29: =INDEX(Table4[],MATCH(I29,Table4[Customer ID]),2) -> Pooja Sharma
I30: C009 | J30: =INDEX(Table4[],MATCH(I30,Table4[Customer ID]),2) -> Karan Desai
I31: C010 | J31: =INDEX(Table4[],MATCH(I31,Table4[Customer ID]),2) -> Anjali Nair
I32: C001 | J32: =INDEX(Table4[],MATCH(I32,Table4[Customer ID]),2) -> Amit Patel
I33: C002 | J33: =INDEX(Table4[],MATCH(I33,Table4[Customer ID]),2) -> Priya Shah
I34: C003 | J34: =INDEX(Table4[],MATCH(I34,Table4[Customer ID]),2) -> Rahul Mehta
... I36: C005 | J36: =INDEX(Table4[],MATCH(I36,Table4[Customer ID]),2) -> Arjun Singh
H38: Task 15
H39: Retrieve the Store Name for every Store ID in the Sales sheet. | I39: S001 | J39: =INDEX(Table5[],MATCH(sales!I39,Table5[Store ID]),2) -> Alpha Store
I40: S002 | J40: =INDEX(Table5[],MATCH(sales!I40,Table5[Store ID]),2) -> Beta Store
I41: S003 | J41: =INDEX(Table5[],MATCH(sales!I41,Table5[Store ID]),2) -> Central Store
I42: S004 | J42: =INDEX(Table5[],MATCH(sales!I42,Table5[Store ID]),2) -> Digital Hub
I43: S005 | J43: =INDEX(Table5[],MATCH(sales!I43,Table5[Store ID]),2) -> Smart World
I44: S001 | J44: =INDEX(Table5[],MATCH(sales!I44,Table5[Store ID]),2) -> Alpha Store
...

Sheet Dashboard
A1: Sales ID | B1: Product ID | C1: Product Name | D1: Category | E1: Brand | F1: Customer Name | G1: Customer City | H1: Store Name | I1: Store City | J1: Quantity | K1: Product Price | L1: Total Sales | M1: Date
A2: SA001 | B2: =INDEX(Table6[#All],MATCH(Dashboard!A2,Table6[[#All],[Sale ID]]),2) -> P1001 | C2: =INDEX(Table2[],MATCH(Dashboard!B2,Table2[Product ID]),2) -> Laptop | D2: =INDEX(Table2[],MATCH(Dashboard!C2,Table2[Product Name]),3) -> Electronics | E2: =INDEX(Table2[],MATCH(Dashboard!B2,Table2[Product ID]),4) -> Dell | F2: =INDEX(Table4[Customer Name],MATCH(INDEX(Table6[Customer ID],MATCH(A2,Table6[Sale ID],0)),Table4[Customer ID],0)) -> Amit Patel | G2: =INDEX(Table4[City],MATCH(INDEX(Table6[Customer ID],MATCH(A2,Table6[Sale ID],0)),Table4[Customer ID],0)) -> Ahmedabad | H2: =INDEX(Table5[Store Name],MATCH(INDEX(Table6[Store ID],MATCH(A2,Table6[Sale ID],0)),Table5[Store ID],0)) -> Alpha Store | I2: =INDEX(Table5[City],MATCH(INDEX(Table6[Store ID],MATCH(A2,Table6[Sale ID],0)),Table5[Store ID],0)) -> Ahmedabad | J2: =INDEX(Table6[Quantity],MATCH(A2,Table6[Sale ID],0)) -> 1 | K2: =INDEX(Table2[Price],MATCH(B2,Table2[Product ID],0)) -> 55000 | L2: =INDEX(Table6[Quantity],MATCH(A2,Table6[Sale ID],0))*INDEX(Table2[Price],MATCH(B2,Table2[Product ID],0)) -> 55000 | M2: =INDEX(Table6[Date],MATCH(A2,Table6[Sale ID],0)) -> 46023

Sheet Report
A1: Transaction Report
A2: Sales ID | B2: SA011
A4: Product ID | B4: =INDEX(Table6[Product ID],MATCH(B2,Table6[Sale ID],0)) -> P1005
A5: Product Name | B5: =INDEX(Table2[Product Name],MATCH(B4,Table2[Product ID],0)) -> Mouse
A6: Category | B6: =INDEX(Table2[Category],MATCH(B4,Table2[Product ID],0)) -> Accessories
A7: Brand | B7: =INDEX(Table2[Brand],MATCH(B4,Table2[Product ID],0)) -> HP
A8: Customer Name | B8: =INDEX(Table4[Customer Name],MATCH(INDEX(Table6[Customer ID],MATCH(B2,Table6[Sale ID],0)),Table4[Customer ID],0)) -> Amit Patel
A9: Customer City | B9: =INDEX(Table4[City],MATCH(INDEX(Table6[Customer ID],MATCH(B2,Table6[Sale ID],0)),Table4[Customer ID],0)) -> Ahmedabad
A10: Store Name | B10: =INDEX(Table5[Store Name],MATCH(INDEX(Table6[Store ID],MATCH(B2,Table6[Sale ID],0)),Table5[Store ID],0)) -> Alpha Store
A11: Store City | B11: =INDEX(Table5[City],MATCH(INDEX(Table6[Store ID],MATCH(B2,Table6[Sale ID],0)),Table5[Store ID],0)) -> Ahmedabad
A12: Quantity | B12: =INDEX(Table6[Quantity],MATCH(B2,Table6[Sale ID],0)) -> 5
A13: Product Price | B13: =INDEX(Table2[Price],MATCH(B4,Table2[Product ID],0)) -> 900
A14: Total Sales | B14: =B12*B13 -> 4500
A15: Date | B15: =INDEX(Table6[Date],MATCH(B2,Table6[Sale ID],0)) -> 46033
